Workbook

Sheet Plantilla
A1: XUVENTUDE DORNEDA · TEMPORADA 2026/2027 · BASE ORIGEN | G1: CUERPO TÉCNICO
A3: Dorsal | B3: Nombre | C3: Jugador | D3: Estado | E3: Notas | G3: Cargo | H3: Nombre | I3: Nombre completo
A4: 1 | B4: David | C4: David Casado Gonzalez | D4: Con ficha | G4: Entrenador | H4: Kata | I4: Fernando Antonio Gundín Eirín
A5: 2 | D5: Vacante
A6: 3 | B6: Cerni | C6: Oscar Cernadas Souto | D6: Con ficha
A7: 4 | D7: Vacante
A8: 5 | B8: Willow | C8: Diego Salpurido García | D8: Con ficha
A9: 6 | D9: Vacante
A10: 7 | B10: Joni | C10: Jonathan Docampo del Río | D10: Con ficha
A11: 8 | D11: Vacante
A12: 9 | D12: Vacante
A13: 10 | B13: Félix | C13: Félix López Graña | D13: Con ficha
A14: 11 | B14: Manuly | C14: Jose M. Bergondo Moreno | D14: Con ficha
A15: 12 | D15: Vacante
A16: 13 | B16: Fonato | C16: Eduardo Ramos Barderas | D16: Con ficha
A17: 14 | B17: Rober | C17: Roberto Jose Rumbo Suarez | D17: Con ficha
A18: 15 | B18: Fran | C18: Francisco Tosar Asorey | D18: Con ficha
A19: 16 | D19: Vacante
A20: 17 | B20: Jesús | C20: Rogelio Jesús Sánchez Fernández | D20: Con ficha
A21: 18 | B21: Marcos | C21: Marcos Chico Lago | D21: Con ficha
A22: 19 | D22: Vacante
A23: 20 | B23: Yess | C23: Jose A. Carvalho Tavares | D23: Con ficha
A24: 21 | B24: Pablo | C24: Pablo Allegue López | D24: Con ficha
A25: 22 | B25: Piwi | C25: Sergio J Casal Varela | D25: Con ficha
A26: 23 | D26: Vacante
A27: 24 | B27: Fede | C27: Federico Laport Rivas | D27: Con ficha
A28: 25 | D28: Vacante
A29: 26 | B29: Santi | C29: Santiago Garabal Callón | D29: Con ficha
A30: 27 | B30: Lesmes | C30: Lesmes Sánchez López | D30: Con ficha
A31: 28 | B31: Jorge | C31: Jorge Puente Longueira | D31: Con ficha
A32: 29 | D32: Vacante
A33: 30 | B33: Mauro | C33: Sergio Blanco Varela | D33: Con ficha
A34: 31 | D34: Vacante
A35: 32 | B35: Rivera | C35: Jose Antonio Rivera | D35: Con ficha
A36: 33 | D36: Vacante
B37: Meilan / Mei | C37: Iván Meilán Seoane | D37: Con ficha | E37: Dorsal pendiente
B38: Cata | C38: Jose Ignacio García Dapia | D38: Con ficha | E38: Dorsal pendiente
B39: Román | C39: Roman G. Torreiro Couso | D39: Con ficha | E39: Dorsal pendiente
B40: Borja | C40: Borja Pita González | D40: Con ficha | E40: Dorsal pendiente
B41: Manu / Manuel | C41: Manuel Blanco Canosa | D41: Con ficha | E41: Dorsal pendiente
...

Sheet Partidos
A1: PARTIDOS · REGISTRO GENERAL DE LA TEMPORADA
A3: ID Partido | B3: Fecha | C3: Tipo | D3: Código | E3: Rival | F3: Local/Visitante | G3: GF | H3: GC | I3: Resultado | J3: Competición | K3: Lugar | L3: Resumen / detalles | M3: Jugador destacado | N3: Notas | O3: Hora quedada | P3: Hora partido | Q3: Equipación | R3: Ficha | S3: Equipación rival | T3: Convocados | U3: A prueba
A4: 1 | B4: 09/08/2026 | C4: Amistoso | D4: Pret_1 | E4: Santa Margarita | F4: Local | G4: 6 | H4: 1 | I4: =IF(OR(G4="",H4=""),"",IF(G4>H4,"Victoria",IF(G4=H4,"Empate","Derrota"))) -> Victoria | J4: Pretemporada | K4: Dexo | L4: Xuventude Dorneda se presentó con 21 jugadores frente a los 12 del Santa Margarita. Con bastante calor, la diferencia física se notó pronto. Dorneda probó 6 jugadores nuevos y dominó el partido en todo momento. Del Santa Margarita destacó el dorsal 2, jugador de medio, zurdo y con buen manejo de balón. | M4: Meilan / Borja | N4: Partido disputado. 21 convocados; 6 jugadores a prueba. | O4: 10:30 | P4: 11:00 | Q4: Blanco / Rojo-Negro / Blanco | R4: =HYPERLINK("#'Pret1'!A1","Info") -> Info | S4: Azul / Azul / Azul | T4: 21 | U4: 6
A5: 2 | B5: 16/08/2026 | C5: Amistoso | D5: Pret_2 | E5: Sporting MAP | F5: Local | G5: 2 | H5: 1 | I5: =IF(OR(G5="",H5=""),"",IF(G5>H5,"Victoria",IF(G5=H5,"Empate","Derrota"))) -> Victoria | J5: Pretemporada | K5: Dexo | L5: Victoria 2-1 del Xuventude Dorneda ante Sporting MAP. | M5: Jorge / Fran | N5: Partido disputado. Victoria 2-1. Goles de Jorge y Fran. | O5: 10:30 | P5: 11:00 | Q5: Blanco / Rojo-Negro / Blanco | R5: =HYPERLINK("#'Pret2'!A1","Info") -> Info | T5: 20 | U5: 5
A6: 3 | B6: 23/08/2026 | C6: Amistoso | D6: Pret_3 | E6: F.C. Rossonero | F6: Visitante | G6: 2 | H6: 3 | I6: =IF(OR(G6="",H6=""),"",IF(G6>H6,"Victoria",IF(G6=H6,"Empate","Derrota"))) -> Derrota | J6: Pretemporada | K6: Eirís | L6: Partido muy competitivo e igualado hasta aproximadamente el minuto 25. Tras los cambios, el Dorneda perdió presencia en el centro del campo y Rossonero pasó a dominar con claridad, aunque inicialmente sin traducirlo en goles. Rossonero hizo el 1-0 y Félix empató 1-1 con un gol desde más allá del medio campo. El 2-1 y el 3-1 llegaron bastante seguidos hacia el tramo final. A falta de unos cinco minutos, Fran marcó el 3-2 definitivo. | N6: Partido disputado. Sistema inicial 1-4-4-2. Goles de Félix y Fran. | O6: 11:30 | P6: 12:00 | Q6: Blanco / Rojo-Negro / Blanco | R6: =HYPERLINK("#'Pret3'!A1","Info") -> Info | S6: Rojo-Negro / Negro / Negro (medias no confirmadas) | T6: 18 | U6: 0
A7: 4 | B7: 30/08/2026 | C7: Amistoso | D7: Pret_4 | E7: Betanzos Norte | F7: Local | G7: 2 | H7: 4 | I7: =IF(OR(G7="",H7=""),"",IF(G7>H7,"Victoria",IF(G7=H7,"Empate","Derrota"))) -> Derrota | J7: Pretemporada | K7: A Marola | L7: El Dorneda se puso 2-0 por delante y dispuso de varias ocasiones muy claras para ampliar la ventaja. Tras los cambios, el equipo se desajustó y Betanzos Norte aprovechó el tramo para marcar cuatro goles en aproximadamente 15 minutos, dando la vuelta al partido hasta el 2-4 definitivo. | N7: Descanso 1-0. Segunda parte: 2-0 y cuatro goles del Betanzos hasta el 2-4. Betanzos Norte: dorsal 21, extremo izquierdo rápido y habilidoso; central izquierdo muy protestón y con muchas dificultades en la salida de balón; dorsal 12, buen jugador actuando como 4 en la salida; dorsal 24, centrocampista de muy buen nivel. | O7: 09:30 | P7: 10:00 | Q7: Blanco / Rojo-Negro / Blanco | R7: =HYPERLINK("#'Pret4'!A1","Info") -> Info | S7: Roja / Azul / Roja | T7: 19 | U7: 3
A8: 5 | B8: 05/09/2026 | C8: Copa | D8: C_32avos | E8: U.D. Narahío | F8: Visitante | I8: =IF(OR(G8="",H8=""),"",IF(G8>H8,"Victoria",IF(G8=H8,"Empate","Derrota"))) | J8: Copa Federación A Coruña | K8: Pendiente | N8: 32avos a partido único. Ambos son de 1ª; Narahío salió primero en el sorteo, por lo que ejerce de local. En caso de empate: penaltis. | R8: Pendiente
A9: 6 | B9: 12-13/09/2026 | C9: Liga | D9: J1 | E9: Pendiente emparejamiento | F9: Pendiente | I9: =IF(OR(G9="",H9=""),"",IF(G9>H9,"Victoria",IF(G9=H9,"Empate","Derrota"))) | J9: Primera Futgal | K9: Pendiente | N9: Jornada oficial RFGF. Concretar rival, sábado/domingo, campo y hora. | R9: Pendiente
A10: 7 | B10: 19-20/09/2026 | C10: Liga | D10: J2 | E10: Pendiente emparejamiento | F10: Pendiente | I10: =IF(OR(G10="",H10=""),"",IF(G10>H10,"Victoria",IF(G10=H10,"Empate","Derrota"))) | J10: Primera Futgal | K10: Pendiente | N10: Jornada oficial RFGF. Concretar rival, sábado/domingo, campo y hora. | R10: Pendiente
A11: 8 | B11: 26-27/09/2026 | C11: Liga | D11: J3 | E11: Pendiente emparejamiento | F11: Pendiente | I11: =IF(OR(G11="",H11=""),"",IF(G11>H11,"Victoria",IF(G11=H11,"Empate","Derrota"))) | J11: Primera Futgal | K11: Pendiente | N11: Jornada oficial RFGF. Concretar rival, sábado/domingo, campo y hora. | R11: Pendiente
A12: 9 | B12: 03-04/10/2026 | C12: Liga | D12: J4 | E12: Pendiente emparejamiento | F12: Pendiente | I12: =IF(OR(G12="",H12=""),"",IF(G12>H12,"Victoria",IF(G12=H12,"Empate","Derrota"))) | J12: Primera Futgal | K12: Pendiente | N12: Jornada oficial RFGF. Concretar rival, sábado/domingo, campo y hora. | R12: Pendiente
A13: 10 | B13: 10-11/10/2026 | C13: Liga | D13: J5 | E13: Pendiente emparejamiento | F13: Pendiente | I13: =IF(OR(G13="",H13=""),"",IF(G13>H13,"Victoria",IF(G13=H13,"Empate","Derrota"))) | J13: Primera Futgal | K13: Pendiente | N13: Jornada oficial RFGF. Concretar rival, sábado/domingo, campo y hora. | R13: Pendiente
A14: 11 | B14: 17-18/10/2026 | C14: Liga | D14: J6 | E14: Pendiente emparejamiento | F14: Pendiente | I14: =IF(OR(G14="",H14=""),"",IF(G14>H14,"Victoria",IF(G14=H14,"Empate","Derrota"))) | J14: Primera Futgal | K14: Pendiente | N14: Jornada oficial RFGF. Concretar rival, sábado/domingo, campo y hora. | R14: Pendiente
A15: 12 | B15: 24-25/10/2026 | C15: Liga | D15: J7 | E15: Pendiente emparejamiento | F15: Pendiente | I15: =IF(OR(G15="",H15=""),"",IF(G15>H15,"Victoria",IF(G15=H15,"Empate","Derrota"))) | J15: Primera Futgal | K15: Pendiente | N15: Jornada oficial RFGF. Concretar rival, sábado/domingo, campo y hora. | R15: Pendiente
A16: 13 | B16: 31/10/2026 | C16: Copa | D16: C_16avos | E16: Pendiente de sorteo (si clasifica) | F16: Pendiente | I16: =IF(OR(G16="",H16=""),"",IF(G16>H16,"Victoria",IF(G16=H16,"Empate","Derrota"))) | J16: Copa Federación A Coruña | K16: Pendiente | N16: 16avos de final. Fecha oficial RFGF: 31/10/2026. Rival, condición y campo pendientes de sorteo y de la clasificación en C_32avos. | R16: Pendiente
A17: 14 | B17: 07-08/11/2026 | C17: Liga | D17: J8 | E17: Pendiente emparejamiento | F17: Pendiente | I17: =IF(OR(G17="",H17=""),"",IF(G17>H17,"Victoria",IF(G17=H17,"Empate","Derrota"))) | J17: Primera Futgal | K17: Pendiente | N17: Jornada oficial RFGF. Concretar rival, sábado/domingo, campo y hora. | R17: Pendiente
A18: 15 | B18: 14-15/11/2026 | C18: Liga | D18: J9 | E18: Pendiente emparejamiento | F18: Pendiente | I18: =IF(OR(G18="",H18=""),"",IF(G18>H18,"Victoria",IF(G18=H18,"Empate","Derrota"))) | J18: Primera Futgal | K18: Pendiente | N18: Jornada oficial RFGF. Concretar rival, sábado/domingo, campo y hora. | R18: Pendiente
A19: 16 | B19: 21-22/11/2026 | C19: Liga | D19: J10 | E19: Pendiente emparejamiento | F19: Pendiente | I19: =IF(OR(G19="",H19=""),"",IF(G19>H19,"Victoria",IF(G19=H19,"Empate","Derrota"))) | J19: Primera Futgal | K19: Pendiente | N19: Jornada oficial RFGF. Concretar rival, sábado/domingo, campo y hora. | R19: Pendiente
... A48: 45 | B48: 19-20/06/2027 | C48: Campeonato Gallego | D48: CG_5 | E48: Pendiente (si clasifica) | F48: Pendiente | I48: =IF(OR(G48="",H48=""),"",IF(G48>H48,"Victoria",IF(G48=H48,"Empate","Derrota"))) | J48: Campeonato Gallego | K48: Pendiente | N48: Fecha oficial RFGF de Campeonato Gallego. Rival, campo y formato pendientes. | R48: Pendiente
I101: =IF(OR(G101="",H101=""),"",IF(G101>H101,"Victoria",IF(G101=H101,"Empate","Derrota")))
I102: =IF(OR(G102="",H102=""),"",IF(G102>H102,"Victoria",IF(G102=H102,"Empate","Derrota")))
I103: =IF(OR(G103="",H103=""),"",IF(G103>H103,"Victoria",IF(G103=H103,"Empate","Derrota")))

Sheet Estadísticas
A1: ESTADÍSTICAS ACUMULADAS · XUVENTUDE DORNEDA 2026/2027
A3: Partidos registrados | B3: =COUNT(Partidos!G4:G103) -> 4
A4: Victorias | B4: =COUNTIF(Partidos!I4:I103,"Victoria") -> 2
A5: Empates | B5: =COUNTIF(Partidos!I4:I103,"Empate") -> 0
A6: Derrotas | B6: =COUNTIF(Partidos!I4:I103,"Derrota") -> 2
A7: Balance goles | B7: =SUM(Partidos!G4:G103)-SUM(Partidos!H4:H103) -> 3
A10: Dorsal | B10: Nombre | C10: Convocatorias | D10: Jugados | E10: Titularidades | F10: Ausencias | G10: Goles | H10: Asistencias | I10: Amarillas | J10: Rojas | K10: Minutos | L10: G+A
A11: 1 | B11: David | C11: 4 | D11: 4 | E11: 3 | F11: 0 | G11: 0 | H11: 0 | I11: 0 | J11: 0 | K11: 0 | L11: =G11+H11 -> 0
A12: 3 | B12: Cerni | C12: 3 | D12: 3 | E12: 2 | F12: 1 | G12: 0 | H12: 0 | I12: 0 | J12: 0 | K12: 0 | L12: =G12+H12 -> 0
A13: 5 | B13: Willow | C13: 4 | D13: 4 | E13: 1 | F13: 0 | G13: 1 | H13: 0 | I13: 0 | J13: 0 | K13: 0 | L13: =G13+H13 -> 1
A14: 7 | B14: Joni | C14: 0 | D14: 0 | E14: 0 | F14: 4 | G14: 0 | H14: 0 | I14: 0 | J14: 0 | K14: 0 | L14: =G14+H14 -> 0
A15: 10 | B15: Félix | C15: 3 | D15: 3 | E15: 3 | F15: 1 | G15: 1 | H15: 0 | I15: 0 | J15: 0 | K15: 0 | L15: =G15+H15 -> 1
A16: 11 | B16: Manuly | C16: 4 | D16: 4 | E16: 0 | F16: 0 | G16: 0 | H16: 0 | I16: 0 | J16: 0 | K16: 0 | L16: =G16+H16 -> 0
A17: 13 | B17: Fonato | C17: 4 | D17: 4 | E17: 3 | F17: 0 | G17: 0 | H17: 0 | I17: 0 | J17: 0 | K17: 0 | L17: =G17+H17 -> 0
A18: 14 | B18: Rober | C18: 3 | D18: 3 | E18: 0 | F18: 1 | G18: 0 | H18: 0 | I18: 0 | J18: 0 | K18: 0 | L18: =G18+H18 -> 0
A19: 15 | B19: Fran | C19: 3 | D19: 3 | E19: 1 | F19: 1 | G19: 2 | H19: 0 | I19: 0 | J19: 0 | K19: 0 | L19: =G19+H19 -> 2
A20: 17 | B20: Jesús | C20: 2 | D20: 2 | E20: 1 | F20: 2 | G20: 0 | H20: 0 | I20: 0 | J20: 0 | K20: 0 | L20: =G20+H20 -> 0
A21: 18 | B21: Marcos | C21: 4 | D21: 4 | E21: 1 | F21: 0 | G21: 0 | H21: 0 | I21: 0 | J21: 0 | K21: 0 | L21: =G21+H21 -> 0
A22: 20 | B22: Yess | C22: 3 | D22: 3 | E22: 0 | F22: 1 | G22: 0 | H22: 0 | I22: 0 | J22: 0 | K22: 0 | L22: =G22+H22 -> 0
... A30: 32 | B30: Rivera | C30: 3 | D30: 3 | E30: 2 | F30: 1 | G30: 0 | H30: 0 | I30: 0 | J30: 0 | K30: 0 | L30: =G30+H30 -> 0
B31: Meilan | C31: 3 | D31: 3 | E31: 2 | F31: 1 | G31: 2 | H31: 1 | I31: 0 | J31: 0 | K31: 0 | L31: =G31+H31 -> 3
B32: Cata | C32: 2 | D32: 2 | E32: 0 | F32: 1 | G32: 1 | H32: 0 | I32: 0 | J32: 0 | K32: 0 | L32: =G32+H32 -> 1
B33: Román | C33: 3 | D33: 3 | E33: 1 | F33: 1 | G33: 0 | H33: 0 | I33: 0 | J33: 0 | K33: 0 | L33: =G33+H33 -> 0
B34: Borja | C34: 4 | D34: 4 | E34: 3 | F34: 0 | G34: 2 | H34: 0 | I34: 0 | J34: 0 | K34: 0 | L34: =G34+H34 -> 2
B35: Manu | C35: 4 | D35: 4 | E35: 2 | F35: 0 | G35: 0 | H35: 0 | I35: 0 | J35: 0 | K35: 0 | L35: =G35+H35 -> 0
B36: Mario | C36: 1 | D36: 1 | E36: 0 | F36: 1 | G36: 0 | H36: 1 | I36: 0 | J36: 0 | K36: 0 | L36: =G36+H36 -> 1
A39: JUGADORES A PRUEBA · PRETEMPORADA
A40: Dorsal | B40: Nombre | C40: Convocatorias | D40: Jugados | E40: Titularidades | F40: Ausencias | G40: Goles | H40: Asistencias | I40: Amarillas | J40: Rojas | K40: Minutos | L40: G+A
B41: Boliche | C41: 3 | D41: 3 | E41: 0 | F41: 0 | G41: 0 | H41: 0 | I41: 0 | J41: 0 | K41: 0 | L41: =G41+H41 -> 0
B42: Abel | C42: 1 | D42: 1 | E42: 0 | F42: 0 | G42: 0 | H42: 0 | I42: 0 | J42: 0 | K42: 0 | L42: =G42+H42 -> 0
B43: Amigo de Yes | C43: 1 | D43: 1 | E43: 0 | F43: 0 | G43: 0 | H43: 0 | I43: 0 | J43: 0 | K43: 0 | L43: =G43+H43 -> 0

Sheet Listas
A1: Campo | B1: Uso
A2: ID Partido | B2: Número único del partido: 1, 2, 3... Sirve para identificar cada encuentro dentro del histórico.
A3: Jugador a prueba | B3: Añádelo a Plantilla con Estado = A prueba, aunque todavía no tenga ficha.
A4: Convocado | B4: Sí/No. Permite contar convocatorias reales.
A5: Estado en partido | B5: Jugó / Convocado sin jugar / Ausente / No disponible / A prueba.
A6: Motivo ausencia | B6: Lesión, trabajo, viaje, decisión técnica, sanción, etc.
A7: Goles y asistencias | B7: Los goles y asistencias se actualizan en la ficha de cada partido y se consolidan en Estadísticas y Goleadores.
A8: Resumen / detalles | B8: Crónica breve o hechos destacados del partido en la hoja Partidos.
A9: Detalle individual | B9: Observación relevante de un jugador en un partido concreto.
A10: Valoración | B10: Escala opcional 1–5 para seguimiento interno.

Sheet Calendario
A1: CALENDARIO · XUVENTUDE DORNEDA 2026/27 | J1: IMAGEN OFICIAL RFGF · CALENDARIO A CORUÑA-FERROL
A3: FINES DE SEMANA LIBRES CONFIRMADOS: 13-14/02/2027 · 26-27/06/2027 (fin del calendario oficial)
A4: ID | B4: Fecha / fin de semana | C4: Código | D4: Competición | E4: Rival | F4: Condición | G4: Estado | H4: Observaciones
A5: 1 | B5: 09/08/2026 | C5: Pret_1 | D5: Pretemporada | E5: Santa Margarita | F5: Local | G5: Jugado · 6-1 | H5: Goles: Meilan 2, Borja 2, Willow 1, Jorge 1.
A6: 2 | B6: 16/08/2026 | C6: Pret_2 | D6: Pretemporada | E6: Sporting MAP | F6: Local | G6: Jugado · 2-1 | H6: Goles: Jorge 1, Fran 1.
A7: 3 | B7: 23/08/2026 | C7: Pret_3 | D7: Pretemporada | E7: F.C. Rossonero | F7: Visitante | G7: Jugado · 2-3 | H7: Eirís · quedada 11:30 · partido 12:00 · goles de Félix y Fran.
A8: 4 | B8: 30/08/2026 | C8: Pret_4 | D8: Pretemporada | E8: Betanzos Norte | F8: Local | G8: Jugado · 2-4 | H8: A Marola · quedada 09:30 · partido 10:00 · goles de Jorge y Cata.
A9: 5 | B9: 05-06/09/2026 | C9: C_32avos | D9: Copa Federación A Coruña | E9: U.D. Narahío | F9: Visitante | G9: Oficial | H9: 32avos a partido único. En caso de empate: penaltis.
A10: 6 | B10: 12-13/09/2026 | C10: J1 | D10: Primera Futgal | E10: Pendiente | F10: Pendiente | G10: Oficial | H10: Rival, día exacto, campo y hora pendientes.
A11: 7 | B11: 19-20/09/2026 | C11: J2 | D11: Primera Futgal | E11: Pendiente | F11: Pendiente | G11: Oficial | H11: Rival, día exacto, campo y hora pendientes.
A12: 8 | B12: 26-27/09/2026 | C12: J3 | D12: Primera Futgal | E12: Pendiente | F12: Pendiente | G12: Oficial | H12: Rival, día exacto, campo y hora pendientes.
A13: 9 | B13: 03-04/10/2026 | C13: J4 | D13: Primera Futgal | E13: Pendiente | F13: Pendiente | G13: Oficial | H13: Rival, día exacto, campo y hora pendientes.
A14: 10 | B14: 10-11/10/2026 | C14: J5 | D14: Primera Futgal | E14: Pendiente | F14: Pendiente | G14: Oficial | H14: Rival, día exacto, campo y hora pendientes.
A15: 11 | B15: 17-18/10/2026 | C15: J6 | D15: Primera Futgal | E15: Pendiente | F15: Pendiente | G15: Oficial | H15: Rival, día exacto, campo y hora pendientes.
A16: 12 | B16: 24-25/10/2026 | C16: J7 | D16: Primera Futgal | E16: Pendiente | F16: Pendiente | G16: Oficial | H16: Rival, día exacto, campo y hora pendientes.
... A31: 27 | B31: 06-07/02/2027 | C31: J19 | D31: Primera Futgal | E31: Pendiente | F31: Pendiente | G31: Oficial | H31: Rival, día exacto, campo y hora pendientes.
A32: — | B32: 13-14/02/2027 | C32: LIBRE | D32: — | E32: — | F32: — | G32: LIBRE | H32: Fin de semana sin jornada de Liga ni fecha de Copa programada.
A33: 28 | B33: 20-21/02/2027 | C33: J20 | D33: Primera Futgal | E33: Pendiente | F33: Pendiente | G33: Oficial | H33: Rival, día exacto, campo y hora pendientes.
A34: 29 | B34: 27-28/02/2027 | C34: J21 | D34: Primera Futgal | E34: Pendiente | F34: Pendiente | G34: Oficial | H34: Rival, día exacto, campo y hora pendientes. | J34: IMAGEN OFICIAL RFGF · CUADRO DE COPA
A35: 30 | B35: 06-07/03/2027 | C35: J22 | D35: Primera Futgal | E35: Pendiente | F35: Pendiente | G35: Oficial | H35: Rival, día exacto, campo y hora pendientes.
A36: 31 | B36: 13-14/03/2027 | C36: J23 | D36: Primera Futgal | E36: Pendiente | F36: Pendiente | G36: Oficial | H36: Rival, día exacto, campo y hora pendientes.
A37: 32 | B37: 20-21/03/2027 | C37: J24 | D37: Primera Futgal | E37: Pendiente | F37: Pendiente | G37: Oficial | H37: Rival, día exacto, campo y hora pendientes.
A38: 33 | B38: 27-28/03/2027 | C38: C_Semis | D38: Copa Federación A Coruña | E38: Pendiente de sorteo | F38: Pendiente | G38: Condicional | H38: Solo si sigue clasificado en Copa.
A39: 34 | B39: 03-04/04/2027 | C39: J25 | D39: Primera Futgal | E39: Pendiente | F39: Pendiente | G39: Oficial | H39: Rival, día exacto, campo y hora pendientes.
A40: 35 | B40: 10-11/04/2027 | C40: J26 | D40: Primera Futgal | E40: Pendiente | F40: Pendiente | G40: Oficial | H40: Rival, día exacto, campo y hora pendientes.
A41: 36 | B41: 17-18/04/2027 | C41: J27 | D41: Primera Futgal | E41: Pendiente | F41: Pendiente | G41: Oficial | H41: Rival, día exacto, campo y hora pendientes.
A42: 37 | B42: 24-25/04/2027 | C42: J28 | D42: Primera Futgal | E42: Pendiente | F42: Pendiente | G42: Oficial | H42: Rival, día exacto, campo y hora pendientes.
A43: 38 | B43: 01-02/05/2027 | C43: J29 | D43: Primera Futgal | E43: Pendiente | F43: Pendiente | G43: Oficial | H43: Rival, día exacto, campo y hora pendientes.
A44: 39 | B44: 08-09/05/2027 | C44: J30 | D44: Primera Futgal | E44: Pendiente | F44: Pendiente | G44: Oficial | H44: Última jornada de Liga.
A45: 40 | B45: 15-16/05/2027 | C45: C_Final | D45: Copa Federación A Coruña | E45: Pendiente | F45: Neutral | G45: Condicional | H45: Final el 15 de mayo si el equipo se clasifica.
A46: 41 | B46: 22-23/05/2027 | C46: CG_1 | D46: Campeonato Gallego | E46: Pendiente | F46: Pendiente | G46: Condicional | H46: Fecha marcada en verde por RFGF; solo si se clasifica.
... A50: 45 | B50: 19-20/06/2027 | C50: CG_5 | D50: Campeonato Gallego | E50: Pendiente | F50: Pendiente | G50: Condicional | H50: Fecha marcada en verde por RFGF; solo si se clasifica.
A51: — | B51: 26-27/06/2027 | C51: LIBRE | D51: — | E51: — | F51: — | G51: LIBRE | H51: Fin de semana posterior a la última fecha oficial marcada del Campeonato Gallego.
A53: Nota: las fechas de Copa y Campeonato Gallego son condicionales. Si el Dorneda queda eliminado o no se clasifica, esos fines de semana pasarán a estar libres.
A55: Leyenda | B55: Pretemporada | C55: Liga | D55: Copa | E55: Campeonato Gallego | F55: Libre
J68: Fuentes
J69: CALENDARIO A CORUÑA-FERROL D.H.-1-2-2B TEMP. 2026-2027.pdf
J70: PLAN COMPETICIONAL A CORUÑA-FERROL (1).pdf
J71: PREVIA-COPA FEDERACION A CORUÑA VETERANOS 2026-2027.pdf

Sheet Goleadores
A1: GOLEADORES · XUVENTUDE DORNEDA 2026/27
A3: Posición | B3: Jugador | C3: Goles | D3: Partidos Jugados | E3: Ratio goles/partido | F3: Partidos con gol
A4: 1 | B4: Jorge | C4: 3 | D4: 4 | E4: =IF(D4=0,0,C4/D4) -> 0.75 | F4: Pret_1, Pret_2, Pret_4
A5: 2 | B5: Fran | C5: 2 | D5: 3 | E5: =IF(D5=0,0,C5/D5) -> 0.66666667 | F5: Pret_2, Pret_3
A6: 2 | B6: Meilan | C6: 2 | D6: 3 | E6: =IF(D6=0,0,C6/D6) -> 0.66666667 | F6: Pret_1
A7: 2 | B7: Borja | C7: 2 | D7: 4 | E7: =IF(D7=0,0,C7/D7) -> 0.5 | F7: Pret_1
A8: 5 | B8: Cata | C8: 1 | D8: 2 | E8: =IF(D8=0,0,C8/D8) -> 0.5 | F8: Pret_4
A9: 5 | B9: Félix | C9: 1 | D9: 3 | E9: =IF(D9=0,0,C9/D9) -> 0.33333333 | F9: Pret_3
A10: 5 | B10: Willow | C10: 1 | D10: 4 | E10: =IF(D10=0,0,C10/D10) -> 0.25 | F10: Pret_1

Sheet Pret1
A1: FICHA DE PARTIDO · XUVENTUDE DORNEDA 2026/27
A3: Código | B3: Pret_1 | H3: Enlace | I3: =HYPERLINK("#'Partidos'!A3","← Volver a Partidos") -> ← Volver a Partidos
A5: Pret_1 · PRETEMPORADA · VICTORIA 6-1
A7: Rival | B7: Santa Margarita | C7: Fecha | D7: 09/08/2026 | E7: Campo | F7: Dexo | G7: Tipo | H7: Amistoso
A8: Quedada | B8: 10:30 | C8: Hora partido | D8: 11:00 | E8: Resultado | F8: 6-1 | G8: A prueba | H8: 6
A9: Equipación Dorneda | B9: Blanco / Rojo-Negro / Blanco | C9: Equipación rival | D9: Azul / Azul / Azul | E9: Convocados | F9: 21 | G9: Código | H9: Pret_1
A10: Kata entrenador | B10: No asistió | C10: Camiseta rival | D10: Azul | E10: Pantalón | F10: Azul | G10: Medias | H10: Azules
A12: RESUMEN DEL PARTIDO
A13: Nos presentamos con 21 jugadores y ellos únicamente con 12. Hizo bastante calor, así que la diferencia física se notó pronto. Probamos 6 jugadores nuevos y dominamos el partido en todo momento. Del Santa Margarita destacó el dorsal 2, jugador del medio, zurdo y con muy buen manejo de balón.
A17: GOLEADORES | D17: 11 INICIAL | G17: AUSENTES
A18: Meilan | B18: 2 | C18: Pret_1 | D18: David Fona Rivera Piwi Cerni Mauro Jesús Meilan Félix Borja Jorge | G18: Joni — lesión Rober — sin información Pablo — sin información Santi — sin información Lesmes — lesión uña del pie
A19: Borja | B19: 2 | C19: Pret_1
A20: Willow | B20: 1 | C20: Pret_1
A21: Jorge | B21: 1 | C21: Pret_1
A23: CONVOCADOS · 21
A24: Nº | B24: Jugador | C24: Tipo | D24: Titular | E24: Goles
A25: 1 | B25: David | C25: Ficha | D25: Sí | E25: 0
A26: 2 | B26: Fonato | C26: Ficha | D26: Sí | E26: 0
A27: 3 | B27: Willow | C27: Ficha | D27: No | E27: 1
A28: 4 | B28: Félix | C28: Ficha | D28: Sí | E28: 0
A29: 5 | B29: Rivera | C29: Ficha | D29: Sí | E29: 0
A30: 6 | B30: Mauro | C30: Ficha | D30: Sí | E30: 0
A31: 7 | B31: Piwi | C31: Ficha | D31: Sí | E31: 0
A32: 8 | B32: Fede | C32: Ficha | D32: No | E32: 0
A33: 9 | B33: Cerni | C33: Ficha | D33: Sí | E33: 0
A34: 10 | B34: Jorge | C34: Ficha | D34: Sí | E34: 1
A35: 11 | B35: Jesús | C35: Ficha | D35: Sí | E35: 0
A36: 12 | B36: Marcos | C36: Ficha | D36: No | E36: 0
... A45: 21 | B45: Yess | C45: Ficha | D45: No | E45: 0
A48: ALINEACIÓN EN CAMPO · 1-4-2-3-1

Sheet Pret2
A1: FICHA DE PARTIDO · XUVENTUDE DORNEDA 2026/27
A3: Código | B3: Pret_2 | H3: Enlace | I3: =HYPERLINK("#'Partidos'!A3","← Volver a Partidos") -> ← Volver a Partidos
A5: Pret_2 · PRETEMPORADA · VICTORIA 2-1
A7: Rival | B7: Sporting MAP | C7: Fecha | D7: 16/08/2026 | E7: Campo | F7: Dexo | G7: Tipo | H7: Amistoso
A8: Quedada | B8: 10:30 | C8: Hora partido | D8: 11:00 | E8: Resultado | F8: 2-1 | G8: A prueba | H8: 5
A9: Equipación Dorneda | B9: Blanco / Rojo-Negro / Blanco | C9: Equipación rival | D9: Pendiente | E9: Convocados | F9: 20 | G9: Código | H9: Pret_2
A10: Kata entrenador | B10: Sí asistió | C10: Camiseta rival | D10: Pendiente | E10: Pantalón | F10: Pendiente | G10: Medias | H10: Pendiente
A12: RESUMEN DEL PARTIDO
A13: Victoria 2-1. Goles de Jorge y Fran. Pendiente de añadir el resumen completo del partido.
A17: GOLEADORES | D17: 11 INICIAL | G17: AUSENTES
A18: Jorge | B18: 1 | C18: Pret_2 | D18: Pendiente | G18: Joni — lesión Félix — viaje a Vigo Pablo — carga muscular Santi — lesión Lesmes — lesión
A19: Fran | B19: 1 | C19: Pret_2
A23: CONVOCADOS · 20
A24: Nº | B24: Jugador | C24: Tipo | D24: Situación | E24: Notas
A25: 1 | B25: David | C25: Ficha | D25: Jugó
A26: 2 | B26: Cerni | C26: Ficha | D26: Jugó
A27: 3 | B27: Fonato | C27: Ficha | D27: Jugó | E27: Fona
A28: 4 | B28: Mauro | C28: Ficha | D28: Jugó
A29: 5 | B29: Marcos | C29: Ficha | D29: Jugó
A30: 6 | B30: Fede | C30: Ficha | D30: Jugó
A31: 7 | B31: Rivera | C31: Ficha | D31: Jugó
A32: 8 | B32: Fran | C32: Ficha | D32: Jugó
A33: 9 | B33: Jesús | C33: Ficha | D33: Jugó
A34: 10 | B34: Manuly | C34: Ficha | D34: Jugó
A35: 11 | B35: Jorge | C35: Ficha | D35: Jugó
A36: 12 | B36: Piwi | C36: Ficha | D36: Jugó
A37: 13 | B37: Willow | C37: Ficha | D37: Jugó
A38: 14 | B38: Yess | C38: Ficha | D38: Jugó | E38: Yes
A39: 15 | B39: Meilan | C39: A prueba | D39: Jugó
A40: 16 | B40: Borja | C40: A prueba | D40: Jugó
A41: 17 | B41: Manu | C41: A prueba | D41: Jugó
A42: 18 | B42: Boliche | C42: A prueba | D42: Jugó
A43: 19 | B43: Román | C43: A prueba | D43: Jugó
A44: 20 | B44: Rober | C44: Ficha | D44: Jugó
A47: ALINEACIÓN EN CAMPO · PENDIENTE
A48: Cuando tengas el 11 inicial, aquí se incorporará el campo con la alineación.

Sheet Pret3
A1: FICHA DE PARTIDO · XUVENTUDE DORNEDA 2026/27
A3: Código | B3: Pret_3 | H3: Enlace | I3: =HYPERLINK("#'Partidos'!A3","← Volver a Partidos") -> ← Volver a Partidos
A5: Pret_3 · PRETEMPORADA · DERROTA 3-2
A7: Rival | B7: F.C. Rossonero | C7: Fecha | D7: 23/08/2026 | E7: Campo | F7: Eirís | G7: Tipo | H7: Amistoso
A8: Quedada | B8: 11:30 | C8: Hora partido | D8: 12:00 | E8: Resultado | F8: Rossonero 3-2 Dorneda | G8: Sistema | H8: 1-4-4-2
A9: Equipación Dorneda | B9: Blanco / Rojo-Negro / Blanco | C9: Equipación rival | D9: Rojo-Negro / Negro / Negro* | E9: Convocados | F9: 18 | G9: A prueba | H9: 0
A10: Kata entrenador | B10: Sí asistió | C10: Medias rival | D10: Negro (no confirmado) | E10: Condición | F10: Visitante | G10: Código | H10: Pret_3
A12: RESUMEN DEL PARTIDO
A13: Partido muy competitivo e igualado hasta aproximadamente el minuto 25. Tras los cambios, el Dorneda perdió presencia en el centro del campo y Rossonero pasó a dominar con claridad, aunque inicialmente sin traducirlo en goles. Rossonero hizo el 1-0 y Félix empató 1-1 con un gol desde más allá del medio campo. El 2-1 y el 3-1 llegaron bastante seguidos hacia el tramo final. A falta de unos cinco minutos, Fran marcó el 3-2 definitivo.
A18: GOLEADORES | D18: 11 INICIAL · 1-4-4-2 | G18: AUSENTES · 8
A19: Félix | B19: 1 | C19: Sin asistencia | D19: David Fona · Rivera · Piwi · Fede Fran · Manu · Román · Borja Félix · Jorge | G19: Cerni — bautizo Joni — lesión Jesús — lesión Santi — lesión Lesmes — lesión Meilan — sin información Cata — sin información Mario — operación de testículos
A20: Fran | B20: 1 | C20: Sin asistencia
A28: CONVOCADOS · 18 · TODOS JUGARON
A29: Nº | B29: Jugador | C29: Tipo | D29: Titular | E29: Goles
A30: 1 | B30: David | C30: Ficha | D30: Sí | E30: 0
A31: 2 | B31: Félix | C31: Ficha | D31: Sí | E31: 1
A32: 3 | B32: Jorge | C32: Ficha | D32: Sí | E32: 0
A33: 4 | B33: Marcos | C33: Ficha | D33: No | E33: 0
A34: 5 | B34: Mauro | C34: Ficha | D34: No | E34: 0
A35: 6 | B35: Willow | C35: Ficha | D35: No | E35: 0
A36: 7 | B36: Román | C36: Ficha | D36: Sí | E36: 0
A37: 8 | B37: Borja | C37: Ficha | D37: Sí | E37: 0
A38: 9 | B38: Fran | C38: Ficha | D38: Sí | E38: 1
A39: 10 | B39: Manu | C39: Ficha | D39: Sí | E39: 0
A40: 11 | B40: Fonato | C40: Ficha | D40: Sí | E40: 0
A41: 12 | B41: Fede | C41: Ficha | D41: Sí | E41: 0
... A47: 18 | B47: Pablo | C47: Ficha | D47: No | E47: 0
A49: Detalle destacado: Félix marcó el 1-1 desde más allá de la línea de medio campo.
A52: ALINEACIÓN EN CAMPO · 1-4-4-2

Sheet Pret4
A1: FICHA DE PARTIDO · XUVENTUDE DORNEDA 2026/27
A3: Código | B3: Pret_4 | H3: Enlace | I3: =HYPERLINK("#'Partidos'!A3","← Volver a Partidos") -> ← Volver a Partidos
A5: Pret_4 · PRETEMPORADA · DERROTA 2-4
A7: Rival | B7: Betanzos Norte | C7: Fecha | D7: 30/08/2026 | E7: Campo | F7: A Marola | G7: Tipo | H7: Amistoso
A8: Quedada | B8: 09:30 | C8: Hora partido | D8: 10:00 | E8: Resultado | F8: Dorneda 2-4 Betanzos | G8: Sistema | H8: 1-4-2-3-1
A9: Equipación Dorneda | B9: Blanco / Rojo-Negro / Blanco | C9: Equipación rival | D9: Roja / Azul / Roja | E9: Convocados | F9: 19 | G9: A prueba | H9: 3
A10: Kata entrenador | B10: Sí asistió | C10: Condición | D10: Local | E10: Incidencias | F10: Ninguna | G10: Código | H10: Pret_4
A12: RESUMEN DEL PARTIDO
A13: El Dorneda se puso 2-0 por delante y dispuso de varias ocasiones muy claras para ampliar la ventaja. Tras los cambios, el equipo se desajustó y Betanzos Norte aprovechó el tramo para marcar cuatro goles en aproximadamente 15 minutos, dando la vuelta al partido hasta el 2-4 definitivo.
A18: GOLES Y ASISTENCIAS | D18: 11 INICIAL · 1-4-2-3-1 | G18: AUSENTES · 10
A19: Jorge | B19: 1 | C19: Asistencia: Meilan | D19: David Marcos · Cerni · Fede · Fona Félix · Manu Meilan · Willow · Borja Jorge | G19: Joni — lesión Fran — lesión Jesús — lesión Yess — lesión Piwi — lesión Santi — lesión Lesmes — lesión Mauro — festival Rivera — festival Román — sin información
A20: Cata | B20: 1 | C20: Asistencia: Mario
A31: CONVOCADOS · 19 · TODOS JUGARON
A32: Nº | B32: Jugador | C32: Tipo | D32: Titular | E32: Goles
A33: 1 | B33: David | C33: Ficha | D33: Sí | E33: 0
A34: 2 | B34: Félix | C34: Ficha | D34: Sí | E34: 0
A35: 3 | B35: Fonato | C35: Ficha | D35: Sí | E35: 0
A36: 4 | B36: Willow | C36: Ficha | D36: Sí | E36: 0
A37: 5 | B37: Marcos | C37: Ficha | D37: Sí | E37: 0
A38: 6 | B38: Cerni | C38: Ficha | D38: Sí | E38: 0
A39: 7 | B39: Meilan | C39: Ficha | D39: Sí | E39: 0
A40: 8 | B40: Jorge | C40: Ficha | D40: Sí | E40: 1
A41: 9 | B41: Borja | C41: Ficha | D41: Sí | E41: 0
A42: 10 | B42: Manu | C42: Ficha | D42: Sí | E42: 0
A43: 11 | B43: Fede | C43: Ficha | D43: Sí | E43: 0
A44: 12 | B44: Cata | C44: Ficha | D44: No | E44: 1
... A51: 19 | B51: Boliche | C51: A prueba | D51: No | E51: 0
A53: OBSERVACIONES · BETANZOS NORTE
A54: Betanzos Norte: dorsal 21, extremo izquierdo rápido y habilidoso; central izquierdo muy protestón y con muchas dificultades en la salida de balón; dorsal 12, buen jugador actuando como 4 en la salida; dorsal 24, centrocampista de muy buen nivel.
A61: ALINEACIÓN EN CAMPO · 1-4-2-3-1
